Workbook
Name Slicer_Day: #N/A
Name Slicer_City: #N/A
Name Slicer_Payment_Method: #N/A
Name Slicer_Purchase_Type: #N/A
Name Slicer_Product: #N/A
Name A: 'Restaurant Data'!$P$5
Name Ag: 'Restaurant Data'!#REF!
Name AllAVG: 'Restaurant Data'!#REF!
Name AllQuantity: 'Restaurant Data'!#REF!
Name Allsal: 'Restaurant Data'!$P$2
Name Alltotal: 'Restaurant Data'!#REF!
Name Alltotals: 'Restaurant Data'!$P$2
Name AV: 'Restaurant Data'!$P$6
Name average: 'Restaurant Data'!$N$8
Name AVG: 'Restaurant Data'!$O$2
Name Bestday: 'Pivot Tables'!$N$4
Name Branch: 'Restaurant Data'!#REF!
Name card: 'Pivot Tables'!$N$2
Name citylist: Dashboard!$T$5:$T$9
Name DN: Dashboard!$D$53
Name manager: 'Pivot Tables'!$N$3
Name NativeTimeline_Date: #N/A
Name NativeTimeline_Date1: #N/A
Name pivots: 'Pivot Tables'!$1:$1048576
Name product: 'Pivot Tables'!$N$1
Name Q: 'Restaurant Data'!$P$5
Name Quantitytotal: 'Restaurant Data'!$Q$2
Name SumQuantity: 'Restaurant Data'!$N$7
Name T: 'Restaurant Data'!$P$4
Name Total: 'Restaurant Data'!#REF!
Name Totalsales: 'Restaurant Data'!$N$2
Name Tuesday: 'Pivot Tables'!$N$4

Sheet Slicers

Sheet Pivot Tables
A1: Row Labels | B1: Total Sales | D1: Row Labels | E1: Sum of Sales | H1: Row Labels | I1: Sum Sales | J1: Average Sales | N1: =INDEX(H2:H6,MATCH(MAX(I2:I6),I2:I6,0)) -> Burger | O1: =MAX(I2:I6) -> 376999.81
A2: Nov | B2: 332114.66 | D2: Paris | E2: 79800.305 | H2: Snack | I2: 48999.804 | J2: 999.996 | N2: =INDEX(H11:H13,MATCH(MAX(I11:I13),I11:I13,0)) -> Credit Card | O2: =MAX(I11:I13) -> 120
A3: 07-Nov | B3: 5200.0023 | D3: Berlin | E3: 100600.13 | H3: Drink | I3: 103200.26 | J3: 2064.0053 | N3: =INDEX(H18:H22,MATCH(MAX(I18:I22),I18:I22,0)) -> Joao Silva | O3: =MAX(I18:I22) -> 241714.12
A4: 08-Nov | B4: 12400.073 | D4: Madrid | E4: 136200.27 | H4: Sandwich | I4: 114641.7 | J4: 2204.648 | N4: Tuesday
A5: 09-Nov | B5: 14200.039 | D5: London | E5: 211201.04 | H5: Fries | I5: 125674.29 | J5: 2464.2018
A6: 10-Nov | B6: 13200.043 | D6: Lisbon | E6: 241714.12 | H6: Burger | I6: 376999.81 | J6: 7249.9963
A7: 11-Nov | B7: 14400.016 | D7: Grand Total | E7: 769515.86 | H7: Grand Total | I7: 769515.86 | J7: 3029.59
A8: 12-Nov | B8: 14000.053
A9: 13-Nov | B9: 27674.451
A10: 14-Nov | B10: 17839.344 | D10: Row Labels | E10: Total Sales | F10: Average Sales | H10: Row Labels | I10: Count of Payment Method
A11: 15-Nov | B11: 13600.031 | D11: Sunday | E11: 107200.3 | F11: 2821.0605 | H11: Cash | I11: 76
A12: 16-Nov | B12: 13600.031 | D12: Monday | E12: 114200.15 | F12: 3005.267 | H12: Credit Card | I12: 120
A13: 17-Nov | B13: 14000.053 | D13: Tuesday | E13: 116674.82 | F13: 3240.9671 | H13: Gift Card | I13: 58
A14: 18-Nov | B14: 14400.111 | D14: Wednesday | E14: 106600.26 | F14: 3135.3016 | H14: Grand Total | I14: 254
A15: 19-Nov | B15: 14000.019 | D15: Thursday | E15: 104400.35 | F15: 2982.8672
A16: 20-Nov | B16: 8200.0466 | D16: Friday | E16: 105400.31 | F16: 2848.657
A17: 21-Nov | B17: 14000.084 | D17: Saturday | E17: 115039.68 | F17: 3195.5468 | H17: Row Labels | I17: Sum Sales
A18: 22-Nov | B18: 13599.992 | D18: Grand Total | E18: 769515.86 | F18: 3029.59 | H18: Joao Silva | I18: 241714.12
A19: 23-Nov | B19: 13800.038 | H19: Pablo Perez | I19: 136200.27
A20: 24-Nov | B20: 13600.026 | D20: Row Labels | E20: Sum of Sales | H20: Remy Monet | I20: 79800.305
A21: 25-Nov | B21: 13399.98 | D21: Drive-thru | E21: 178600.47 | H21: Tom Jackson | I21: 211201.04
A22: 26-Nov | B22: 13200.064 | D22: In-store | E22: 285714 | H22: Walter Muller | I22: 100600.13
A23: 27-Nov | B23: 13399.98 | D23: Online | E23: 305201.39 | H23: Grand Total | I23: 769515.86
A24: 28-Nov | B24: 13400.045 | D24: Grand Total | E24: 769515.86
A25: 29-Nov | B25: 13400.045
A26: 30-Nov | B26: 13600.091
A27: Dec | B27: 437401.2 | D27: Row Labels | E27: Sum of Sales | F27: Sum of Quantity
A28: 01-Dec | B28: 13400.114 | D28: Nov | E28: 332114.66 | F28: 50509.07
A29: 02-Dec | B29: 14000.053 | D29: Dec | E29: 437401.2 | F29: 66486.24
A30: 03-Dec | B30: 14000.053 | D30: Grand Total | E30: 769515.86 | F30: 116995.31
A31: 04-Dec | B31: 9000.1007
A32: 05-Dec | B32: 14200.039
A33: 06-Dec | B33: 14000.122
A34: 07-Dec | B34: 14000.053
A35: 08-Dec | B35: 14200.1
A36: 09-Dec | B36: 14600.062
A37: 10-Dec | B37: 14600.062
A38: 11-Dec | B38: 15000.088
A39: 12-Dec | B39: 14600.062
A40: 13-Dec | B40: 14600.062
...

Sheet Restaurant Data
A1: Order ID | B1: Date | C1: Month | D1: Product | E1: Price | F1: Quantity | G1: Purchase Type | H1: Payment Method | I1: Manager | J1: City | K1: Sales | L1: Day
A2: 10452 | B2: 44872 | C2: =TEXT(Table1[[#This Row],[Date]],"mmmm") -> November | D2: Fries | E2: 3.49 | F2: 573.07 | G2: Online | H2: Gift Card | I2: Tom Jackson | J2: London | K2: =E2*F2 -> 2000.0143 | L2: =TEXT(A2,"dddd") -> Sunday | N2: =SUM(K:K) -> 769515.86
A3: 10453 | B3: 44872 | C3: =TEXT(Table1[[#This Row],[Date]],"mmmm") -> November | D3: Drink | E3: 2.95 | F3: 745.76 | G3: Online | H3: Gift Card | I3: Pablo Perez | J3: Madrid | K3: =E3*F3 -> 2199.992 | L3: =TEXT(A3,"dddd") -> Monday | N3: All
A4: 10454 | B4: 44872 | C4: =TEXT(Table1[[#This Row],[Date]],"mmmm") -> November | D4: Snack | E4: 4.99 | F4: 200.4 | G4: In-store | H4: Gift Card | I4: Joao Silva | J4: Lisbon | K4: =E4*F4 -> 999.996 | L4: =TEXT(A4,"dddd") -> Tuesday | N4: November | P4: =SUMIFS('Restaurant Data'!K:K,'Restaurant Data'!J:J,IF('Main Dashboard'!D4="All","<>",'Main Dashboard'!D4),'Restaurant Data'!C:C,IF('Main Dashboard'!N4="All","<>",'Main Dashboard'!N4),'Restaurant Data'!D:D,IF('Main Dashboard'!I4="All","<>",'Main Dashboard'!I4)) -> 769515.86
A5: 10455 | B5: 44873 | C5: =TEXT(Table1[[#This Row],[Date]],"mmmm") -> November | D5: Burger | E5: 12.99 | F5: 569.67 | G5: In-store | H5: Credit Card | I5: Walter Muller | J5: Berlin | K5: =E5*F5 -> 7400.0133 | L5: =TEXT(A5,"dddd") -> Wednesday | N5: December | P5: =SUMIFS('Restaurant Data'!F:F,'Restaurant Data'!J:J,IF('Main Dashboard'!D4="All","<>",'Main Dashboard'!D4),'Restaurant Data'!C:C,IF('Main Dashboard'!N4="All","<>",'Main Dashboard'!N4),'Restaurant Data'!D:D,IF('Main Dashboard'!I4="All","<>",'Main Dashboard'!I4)) -> 116995.31 | R5: Final Dash
A6: 10456 | B6: 44873 | C6: =TEXT(Table1[[#This Row],[Date]],"mmmm") -> November | D6: Sandwich | E6: 9.95 | F6: 201.01 | G6: In-store | H6: Credit Card | I6: Walter Muller | J6: Berlin | K6: =E6*F6 -> 2000.0495 | L6: =TEXT(A6,"dddd") -> Thursday | P6: =IFERROR(AVERAGEIFS('Restaurant Data'!K:K,'Restaurant Data'!J:J,IF('Main Dashboard'!D4="All","<>",'Main Dashboard'!D4),'Restaurant Data'!C:C,IF('Main Dashboard'!N4="All","<>",'Main Dashboard'!N4),'Restaurant Data'!D:D,IF('Main Dashboard'!I4="All","<>",'Main Dashboard'!I4)),"") -> 3029.59
A7: 10457 | B7: 44873 | C7: =TEXT(Table1[[#This Row],[Date]],"mmmm") -> November | D7: Fries | E7: 3.49 | F7: 573.07 | G7: In-store | H7: Credit Card | I7: Remy Monet | J7: Paris | K7: =E7*F7 -> 2000.0143 | L7: =TEXT(A7,"dddd") -> Friday | N7: =SUM(F:F) -> 116995.31
A8: 10459 | B8: 44873 | C8: =TEXT(Table1[[#This Row],[Date]],"mmmm") -> November | D8: Snack | E8: 4.99 | F8: 200.4 | G8: In-store | H8: Credit Card | I8: Walter Muller | J8: Berlin | K8: =E8*F8 -> 999.996 | L8: =TEXT(A8,"dddd") -> Sunday | N8: =AVERAGE(K:K) -> 3029.59
A9: 10460 | B9: 44874 | C9: =TEXT(Table1[[#This Row],[Date]],"mmmm") -> November | D9: Burger | E9: 12.99 | F9: 554.27 | G9: In-store | H9: Credit Card | I9: Remy Monet | J9: Paris | K9: =E9*F9 -> 7199.9673 | L9: =TEXT(A9,"dddd") -> Monday
A10: 10461 | B10: 44874 | C10: =TEXT(Table1[[#This Row],[Date]],"mmmm") -> November | D10: Sandwich | E10: 9.95 | F10: 201.01 | G10: In-store | H10: Credit Card | I10: Remy Monet | J10: Paris | K10: =E10*F10 -> 2000.0495 | L10: =TEXT(A10,"dddd") -> Tuesday
A11: 10462 | B11: 44874 | C11: =TEXT(Table1[[#This Row],[Date]],"mmmm") -> November | D11: Fries | E11: 3.49 | F11: 573.07 | G11: In-store | H11: Credit Card | I11: Remy Monet | J11: Paris | K11: =E11*F11 -> 2000.0143 | L11: =TEXT(A11,"dddd") -> Wednesday
A12: 10463 | B12: 44874 | C12: =TEXT(Table1[[#This Row],[Date]],"mmmm") -> November | D12: Drink | E12: 2.95 | F12: 677.97 | G12: In-store | H12: Credit Card | I12: Remy Monet | J12: Paris | K12: =E12*F12 -> 2000.0115 | L12: =TEXT(A12,"dddd") -> Thursday
A13: 10464 | B13: 44874 | C13: =TEXT(Table1[[#This Row],[Date]],"mmmm") -> November | D13: Snack | E13: 4.99 | F13: 200.4 | G13: In-store | H13: Credit Card | I13: Remy Monet | J13: Paris | K13: =E13*F13 -> 999.996 | L13: =TEXT(A13,"dddd") -> Friday
A14: 10465 | B14: 44875 | C14: =TEXT(Table1[[#This Row],[Date]],"mmmm") -> November | D14: Burger | E14: 12.99 | F14: 554.27 | G14: In-store | H14: Credit Card | I14: Pablo Perez | J14: Madrid | K14: =E14*F14 -> 7199.9673 | L14: =TEXT(A14,"dddd") -> Saturday
A15: 10466 | B15: 44875 | C15: =TEXT(Table1[[#This Row],[Date]],"mmmm") -> November | D15: Sandwich | E15: 9.95 | F15: 201.01 | G15: In-store | H15: Credit Card | I15: Pablo Perez | J15: Madrid | K15: =E15*F15 -> 2000.0495 | L15: =TEXT(A15,"dddd") -> Sunday
A16: 10467 | B16: 44875 | C16: =TEXT(Table1[[#This Row],[Date]],"mmmm") -> November | D16: Fries | E16: 3.49 | F16: 573.07 | G16: In-store | H16: Credit Card | I16: Pablo Perez | J16: Madrid | K16: =E16*F16 -> 2000.0143 | L16: =TEXT(A16,"dddd") -> Monday
A17: 10468 | B17: 44875 | C17: =TEXT(Table1[[#This Row],[Date]],"mmmm") -> November | D17: Drink | E17: 2.95 | F17: 677.97 | G17: In-store | H17: Credit Card | I17: Pablo Perez | J17: Madrid | K17: =E17*F17 -> 2000.0115 | L17: =TEXT(A17,"dddd") -> Tuesday
A18: 10470 | B18: 44876 | C18: =TEXT(Table1[[#This Row],[Date]],"mmmm") -> November | D18: Burger | E18: 12.99 | F18: 554.27 | G18: In-store | H18: Credit Card | I18: Pablo Perez | J18: Madrid | K18: =E18*F18 -> 7199.9673 | L18: =TEXT(A18,"dddd") -> Thursday
A19: 10471 | B19: 44876 | C19: =TEXT(Table1[[#This Row],[Date]],"mmmm") -> November | D19: Sandwich | E19: 9.95 | F19: 201.01 | G19: In-store | H19: Credit Card | I19: Pablo Perez | J19: Madrid | K19: =E19*F19 -> 2000.0495 | L19: =TEXT(A19,"dddd") -> Friday
A20: 10472 | B20: 44876 | C20: =TEXT(Table1[[#This Row],[Date]],"mmmm") -> November | D20: Fries | E20: 3.49 | F20: 630.37 | G20: In-store | H20: Credit Card | I20: Pablo Perez | J20: Madrid | K20: =E20*F20 -> 2199.9913 | L20: =TEXT(A20,"dddd") -> Saturday
... A255: 10713 | B255: 44924 | C255: =TEXT(Table1[[#This Row],[Date]],"mmmm") -> December | D255: Drink | E255: 2.95 | F255: 677.97 | G255: Drive-thru | H255: Gift Card | I255: Walter Muller | J255: Berlin | K255: =E255*F255 -> 2000.0115 | L255: =TEXT(A255,"dddd") -> Tuesday
L259: ="Best Day: "&Bestday -> Best Day: Tuesday | M259: ="Top Manager:"&manager -> Top Manager:Joao Silva
J260: ="🏆 "&Branch&" "&"Total Sales: "&TEXT(Total,"$#,##0") -> #REF!

Sheet Dashboard
H2: All
H3: Online
H4: Drink | R4: All | T4: All
H5: All | R5: {=_xlfn.UNIQUE(Table1[Product])} -> Fries | S5: Lisbon | T5: Lisbon | U5: =SUMIFS('Restaurant Data'!K:K,'Restaurant Data'!J:J,Dashboard!S5) -> 241714.12
R6: Drink | T6: London | V6: =SUMIFS('Restaurant Data'!K:K,'Restaurant Data'!J:J,Dashboard!T6) -> 211201.04
R7: Snack | T7: Paris | V7: =SUMIFS('Restaurant Data'!K:K,'Restaurant Data'!J:J,Dashboard!T7) -> 79800.305
R8: Burger | T8: Madrid | V8: =SUMIFS('Restaurant Data'!K:K,'Restaurant Data'!J:J,Dashboard!T8) -> 136200.27
R9: Sandwich | T9: Berlin | V9: =SUMIFS('Restaurant Data'!K:K,'Restaurant Data'!J:J,Dashboard!T9) -> 100600.13
B52: 332114.66
B53: 437401.2 | D53: =IFERROR((B53-B52)/B52,0) -> 0.31701866

Sheet Main Dashboard
H2: Restaurant Performance Dashboard
C4: City: | D4: All | H4: Product: | I4: All | M4: Month: | N4: All
